Workbook

Sheet 안내
A1: Cobbleventure 포켓몬 바이옴·세대 스폰 카탈로그
A4: 전체 포켓몬 | C4: Cobblemon 구현 | E4: COBBLEVERSE 자연스폰 | G4: 자연스폰 없음
A5: =COUNTA('포켓몬_요약'!A5:A1029) | C5: =COUNTIF('포켓몬_요약'!I5:I1029,"예") | E5: =COUNTIF('포켓몬_요약'!K5:K1029,"예") | G5: =COUNTIF('포켓몬_요약'!T5:T1029,"없음")
A8: 사용 순서
A9: 1 | B9: ‘포켓몬_요약’에서 1,025종의 기본 세대, 구현 여부와 자연 스폰 유무를 확인합니다.
A10: 2 | B10: ‘바이옴_요약’과 ‘바이옴_태그’에서 실제 조건 태그와 현재 지역 바이옴의 연결을 확인합니다.
A11: 3 | B11: ‘스폰_편집’의 노란색 열에서 적용 여부, 허용 세대 월드, 지역, 바이옴, 가중치와 레벨을 수정합니다.
A12: 4 | B12: ‘지역_바이옴’에서 1세대 지역 3~8의 바이옴 풀과 스폰 프로필을 확정합니다.
A13: 5 | B13: 반영 시 관리키·원본파일·스폰ID로 원본 엔트리를 찾아 덮어쓰기 JSON을 생성합니다.
A15: 중요한 해석 기준
A16: • Cobblemon 1.7.3은 1,025종의 종 JSON을 포함하지만 implemented=true는 851종입니다.
A17: • COBBLEVERSE DP v31은 1,017종에 자연 스폰 파일을 제공합니다. 타입:널, 실버디, 멜메탈, 가라르 화석 4종, 타부자고는 자연 스폰 파일이 없습니다.
A18: • 세대 중심 혼합 정책의 타 세대 혼합 비율은 기존 문서에서도 미결정이므로, 현재 엑셀의 기본 허용 월드는 중심 세대 1개로 시작합니다.
A19: • COBBLEVERSE는 All Rights Reserved입니다. 이 워크북은 내부 분석·편집 참고용이며 원본 팩·자산을 재배포하지 않습니다.

Sheet 스폰_편집
A1: Cobblemon · COBBLEVERSE 바이옴별 스폰 편집표
A2: 노란색 열만 수정합니다. 빈 바이옴·레벨 덮어쓰기는 원본 유지, 가중치 배율 1은 원본 유지입니다. 지역 후보는 현재 region_01~02의 바이옴 태그를 부분 해석한 참고값입니다.
A4: 관리키 | B4: 적용여부_편집 | C4: 변경상태 | D4: 덱스번호 | E4: 한글명 | F4: 영문ID | G4: 포켓몬선택자 | H4: 폼·속성 | I4: 기본세대 | J4: 폼도입세대 | K4: 중심세대 | L4: 권장차원 | M4: 허용세대월드_편집 | N4: 지역후보_추정 | O4: 지역배정_편집 | P4: 원본바이옴 | Q4: 바이옴_편집 | R4: 적용바이옴 | S4: 제외바이옴 | T4: 희귀도 | U4: 원본가중치 | V4: 가중치배율_편집 | W4: 적용가중치 | X4: 원본레벨 | Y4: 레벨_편집 | Z4: 적용레벨 | AA4: 위치유형 | AB4: 시간 | AC4: 날씨 | AD4: Y범위 | AE4: 광량 | AF4: 하늘노출 | AG4: 구조물 | AH4: 필요블록 | AI4: 기타조건 | AJ4: 원본상태 | AK4: 원본활성 | AL4: 출처 | AM4: 원본파일 | AN4: 스폰ID | AO4: 스폰타입 | AP4: 프리셋 | AQ4: 조건JSON | AR4: 제외조건JSON | AS4: 가중치보정JSON | AT4: 메모_편집
A5: 0000_pidgey_herd.json::pidgey-herd-test::001 | B5: 제외 | C5: =IF(OR(B5<>AK5,M5<>L5,O5<>"",Q5<>"",V5<>1,Y5<>"",AT5<>""),"수정","원본") | E5: pidgey; | F5: pidgey; | G5: pidgey; pidgeotto; pidgeotto; pidgeot | H5: pidgeotto; pidgeotto; pidgeot | N5: region_01; region_02 | P5: #cobblemon:is_overworld | R5: =IF(Q5="",P5,Q5) | T5: common | U5: 100 | V5: 1 | W5: =IF(OR(U5="",V5=""),U5,U5*V5) | X5: 10-40 | Z5: =IF(Y5="",X5,Y5) | AA5: grounded | AI5: {"spawn":{"herdablePokemon":[{"levelRange":"10-40","levelRangeOffset":"-3-3","pokemon":"pidgey","weight":1},{"isLeader":true,"levelRange":"21-30","levelRangeOffset":"4-7","maxTimes":1,"pokemon":"pidgeotto","weight":1},{"isLeader":false,"levelRange":"31-40","levelRangeOffset":"-3-3","pokemon":"pidgeotto","weight":5},{"isLeader":true,"levelRange":"31-40","levelRangeOffset":"4-7","maxTimes":1,"pokemon":"pidgeot","weight":1}],"maxHerdSize":5,"minDistanceBetweenSpawns":1.5}} | AJ5: Cobblemon 전용 | AK5: 제외 | AL5: Cobblemon 1.7.3 | AM5: data/cobblemon/spawn_pool_world/0000_pidgey_herd.json | AN5: pidgey-herd-test | AO5: pokemon-herd | AP5: natural | AQ5: {"biomes":["#cobblemon:is_overworld"]}
A6: 0001_bulbasaur.json::bulbasaur-1::001 | B6: 사용 | C6: =IF(OR(B6<>AK6,M6<>L6,O6<>"",Q6<>"",V6<>1,Y6<>"",AT6<>""),"수정","원본") | D6: 1 | E6: 이상해씨 | F6: bulbasaur | G6: bulbasaur | I6: 1 | K6: 1 | L6: cobbleventure:generation_1 | M6: cobbleventure:generation_1 | P6: #cobblemon:is_jungle; #cobblemon:is_tropical_island | R6: =IF(Q6="",P6,Q6) | T6: ultra-rare | U6: 6 | V6: 1 | W6: =IF(OR(U6="",V6=""),U6,U6*V6) | X6: 5-32 | Z6: =IF(Y6="",X6,Y6) | AA6: grounded | AE6: sky 8-15 | AJ6: Cobblemon 동일 | AK6: 사용 | AL6: COBBLEVERSE 1.7.42 / DP v31 | AM6: data/cobblemon/spawn_pool_world/0001_bulbasaur.json | AN6: bulbasaur-1 | AO6: pokemon | AP6: natural | AQ6: {"biomes":["#cobblemon:is_jungle","#cobblemon:is_tropical_island"],"maxSkyLight":15,"minSkyLight":8}
A7: 0002_ivysaur.json::ivysaur-1::001 | B7: 사용 | C7: =IF(OR(B7<>AK7,M7<>L7,O7<>"",Q7<>"",V7<>1,Y7<>"",AT7<>""),"수정","원본") | D7: 2 | E7: 이상해풀 | F7: ivysaur | G7: ivysaur | I7: 1 | K7: 1 | L7: cobbleventure:generation_1 | M7: cobbleventure:generation_1 | P7: #cobblemon:is_jungle; #cobblemon:is_tropical_island | R7: =IF(Q7="",P7,Q7) | T7: ultra-rare | U7: 3.6 | V7: 1 | W7: =IF(OR(U7="",V7=""),U7,U7*V7) | X7: 16-40 | Z7: =IF(Y7="",X7,Y7) | AA7: grounded | AE7: sky 8-15 | AJ7: Cobblemon 동일 | AK7: 사용 | AL7: COBBLEVERSE 1.7.42 / DP v31 | AM7: data/cobblemon/spawn_pool_world/0002_ivysaur.json | AN7: ivysaur-1 | AO7: pokemon | AP7: natural | AQ7: {"biomes":["#cobblemon:is_jungle","#cobblemon:is_tropical_island"],"maxSkyLight":15,"minSkyLight":8}
A8: 0003_venusaur.json::venusaur-1::001 | B8: 사용 | C8: =IF(OR(B8<>AK8,M8<>L8,O8<>"",Q8<>"",V8<>1,Y8<>"",AT8<>""),"수정","원본") | D8: 3 | E8: 이상해꽃 | F8: venusaur | G8: venusaur | I8: 1 | K8: 1 | L8: cobbleventure:generation_1 | M8: cobbleventure:generation_1 | P8: #cobblemon:is_jungle; #cobblemon:is_tropical_island | R8: =IF(Q8="",P8,Q8) | T8: ultra-rare | U8: 0.4 | V8: 1 | W8: =IF(OR(U8="",V8=""),U8,U8*V8) | X8: 32-52 | Z8: =IF(Y8="",X8,Y8) | AA8: grounded | AE8: sky 8-15 | AJ8: Cobblemon 동일 | AK8: 사용 | AL8: COBBLEVERSE 1.7.42 / DP v31 | AM8: data/cobblemon/spawn_pool_world/0003_venusaur.json | AN8: venusaur-1 | AO8: pokemon | AP8: natural | AQ8: {"biomes":["#cobblemon:is_jungle","#cobblemon:is_tropical_island"],"maxSkyLight":15,"minSkyLight":8}
A9: 0004_charmander.json::charmander-1::001 | B9: 사용 | C9: =IF(OR(B9<>AK9,M9<>L9,O9<>"",Q9<>"",V9<>1,Y9<>"",AT9<>""),"수정","원본") | D9: 4 | E9: 파이리 | F9: charmander | G9: charmander | I9: 1 | K9: 1 | L9: cobbleventure:generation_1 | M9: cobbleventure:generation_1 | P9: #cobblemon:is_hills; #cobblemon:is_volcanic | R9: =IF(Q9="",P9,Q9) | T9: ultra-rare | U9: 6 | V9: 1 | W9: =IF(OR(U9="",V9=""),U9,U9*V9) | X9: 5-31 | Z9: =IF(Y9="",X9,Y9) | AA9: grounded | AC9: 비=False | AE9: sky 8-15 | AJ9: Cobblemon 동일 | AK9: 사용 | AL9: COBBLEVERSE 1.7.42 / DP v31 | AM9: data/cobblemon/spawn_pool_world/0004_charmander.json | AN9: charmander-1 | AO9: pokemon | AP9: natural | AQ9: {"biomes":["#cobblemon:is_hills","#cobblemon:is_volcanic"],"isRaining":false,"maxSkyLight":15,"minSkyLight":8}
A10: 0004_charmander.json::charmander-2::002 | B10: 사용 | C10: =IF(OR(B10<>AK10,M10<>L10,O10<>"",Q10<>"",V10<>1,Y10<>"",AT10<>""),"수정","원본") | D10: 4 | E10: 파이리 | F10: charmander | G10: charmander | I10: 1 | K10: 1 | L10: cobbleventure:generation_1 | M10: cobbleventure:generation_1 | P10: #cobblemon:nether/is_basalt | R10: =IF(Q10="",P10,Q10) | T10: ultra-rare | U10: 6 | V10: 1 | W10: =IF(OR(U10="",V10=""),U10,U10*V10) | X10: 5-31 | Z10: =IF(Y10="",X10,Y10) | AA10: grounded | AJ10: Cobblemon 동일 | AK10: 사용 | AL10: COBBLEVERSE 1.7.42 / DP v31 | AM10: data/cobblemon/spawn_pool_world/0004_charmander.json | AN10: charmander-2 | AO10: pokemon | AP10: natural | AQ10: {"biomes":["#cobblemon:nether/is_basalt"]}
A11: 0005_charmeleon.json::charmeleon-1::001 | B11: 사용 | C11: =IF(OR(B11<>AK11,M11<>L11,O11<>"",Q11<>"",V11<>1,Y11<>"",AT11<>""),"수정","원본") | D11: 5 | E11: 리자드 | F11: charmeleon | G11: charmeleon | I11: 1 | K11: 1 | L11: cobbleventure:generation_1 | M11: cobbleventure:generation_1 | P11: #cobblemon:is_hills; #cobblemon:is_volcanic | R11: =IF(Q11="",P11,Q11) | T11: ultra-rare | U11: 3.6 | V11: 1 | W11: =IF(OR(U11="",V11=""),U11,U11*V11) | X11: 16-40 | Z11: =IF(Y11="",X11,Y11) | AA11: grounded | AC11: 비=False | AE11: sky 8-15 | AJ11: Cobblemon 동일 | AK11: 사용 | AL11: COBBLEVERSE 1.7.42 / DP v31 | AM11: data/cobblemon/spawn_pool_world/0005_charmeleon.json | AN11: charmeleon-1 | AO11: pokemon | AP11: natural | AQ11: {"biomes":["#cobblemon:is_hills","#cobblemon:is_volcanic"],"isRaining":false,"maxSkyLight":15,"minSkyLight":8}
A12: 0005_charmeleon.json::charmeleon-2::002 | B12: 사용 | C12: =IF(OR(B12<>AK12,M12<>L12,O12<>"",Q12<>"",V12<>1,Y12<>"",AT12<>""),"수정","원본") | D12: 5 | E12: 리자드 | F12: charmeleon | G12: charmeleon | I12: 1 | K12: 1 | L12: cobbleventure:generation_1 | M12: cobbleventure:generation_1 | P12: #cobblemon:nether/is_basalt | R12: =IF(Q12="",P12,Q12) | T12: ultra-rare | U12: 3.6 | V12: 1 | W12: =IF(OR(U12="",V12=""),U12,U12*V12) | X12: 16-40 | Z12: =IF(Y12="",X12,Y12) | AA12: grounded | AJ12: Cobblemon 동일 | AK12: 사용 | AL12: COBBLEVERSE 1.7.42 / DP v31 | AM12: data/cobblemon/spawn_pool_world/0005_charmeleon.json | AN12: charmeleon-2 | AO12: pokemon | AP12: natural | AQ12: {"biomes":["#cobblemon:nether/is_basalt"]}
A13: 0006_charizard.json::charizard-1::001 | B13: 사용 | C13: =IF(OR(B13<>AK13,M13<>L13,O13<>"",Q13<>"",V13<>1,Y13<>"",AT13<>""),"수정","원본") | D13: 6 | E13: 리자몽 | F13: charizard | G13: charizard | I13: 1 | K13: 1 | L13: cobbleventure:generation_1 | M13: cobbleventure:generation_1 | P13: #cobblemon:is_hills; #cobblemon:is_volcanic | R13: =IF(Q13="",P13,Q13) | T13: ultra-rare | U13: 0.4 | V13: 1 | W13: =IF(OR(U13="",V13=""),U13,U13*V13) | X13: 36-53 | Z13: =IF(Y13="",X13,Y13) | AA13: grounded | AC13: 비=False | AE13: sky 8-15 | AJ13: Cobblemon 동일 | AK13: 사용 | AL13: COBBLEVERSE 1.7.42 / DP v31 | AM13: data/cobblemon/spawn_pool_world/0006_charizard.json | AN13: charizard-1 | AO13: pokemon | AP13: natural | AQ13: {"biomes":["#cobblemon:is_hills","#cobblemon:is_volcanic"],"isRaining":false,"maxSkyLight":15,"minSkyLight":8}
A14: 0006_charizard.json::charizard-2::002 | B14: 사용 | C14: =IF(OR(B14<>AK14,M14<>L14,O14<>"",Q14<>"",V14<>1,Y14<>"",AT14<>""),"수정","원본") | D14: 6 | E14: 리자몽 | F14: charizard | G14: charizard | I14: 1 | K14: 1 | L14: cobbleventure:generation_1 | M14: cobbleventure:generation_1 | P14: #cobblemon:nether/is_basalt | R14: =IF(Q14="",P14,Q14) | T14: ultra-rare | U14: 0.4 | V14: 1 | W14: =IF(OR(U14="",V14=""),U14,U14*V14) | X14: 36-53 | Z14: =IF(Y14="",X14,Y14) | AA14: grounded | AJ14: Cobblemon 동일 | AK14: 사용 | AL14: COBBLEVERSE 1.7.42 / DP v31 | AM14: data/cobblemon/spawn_pool_world/0006_charizard.json | AN14: charizard-2 | AO14: pokemon | AP14: natural | AQ14: {"biomes":["#cobblemon:nether/is_basalt"]}
A15: 0007_squirtle.json::squirtle-1::001 | B15: 사용 | C15: =IF(OR(B15<>AK15,M15<>L15,O15<>"",Q15<>"",V15<>1,Y15<>"",AT15<>""),"수정","원본") | D15: 7 | E15: 꼬부기 | F15: squirtle | G15: squirtle | I15: 1 | K15: 1 | L15: cobbleventure:generation_1 | M15: cobbleventure:generation_1 | N15: region_01; region_02 | P15: #cobblemon:is_freshwater; #cobblemon:is_hills; #cobblemon:is_jungle; #cobblemon:is_temperate; #cobblemon:is_tropical_island | R15: =IF(Q15="",P15,Q15) | S15: #cobblemon:is_freezing | T15: ultra-rare | U15: 6 | V15: 1 | W15: =IF(OR(U15="",V15=""),U15,U15*V15) | X15: 5-31 | Z15: =IF(Y15="",X15,Y15) | AA15: grounded | AE15: sky 8-15 | AH15: 주변=minecraft:water | AJ15: Cobblemon 동일 | AK15: 사용 | AL15: COBBLEVERSE 1.7.42 / DP v31 | AM15: data/cobblemon/spawn_pool_world/0007_squirtle.json | AN15: squirtle-1 | AO15: pokemon | AP15: natural | AQ15: {"biomes":["#cobblemon:is_freshwater","#cobblemon:is_hills","#cobblemon:is_jungle","#cobblemon:is_temperate","#cobblemon:is_tropical_island"],"maxSkyLight":15,"minSkyLight":8,"neededNearbyBlocks":["minecraft:water"]} | AR15: {"biomes":["#cobblemon:is_freezing"]}
A16: 0007_squirtle.json::squirtle-2::002 | B16: 사용 | C16: =IF(OR(B16<>AK16,M16<>L16,O16<>"",Q16<>"",V16<>1,Y16<>"",AT16<>""),"수정","원본") | D16: 7 | E16: 꼬부기 | F16: squirtle | G16: squirtle | I16: 1 | K16: 1 | L16: cobbleventure:generation_1 | M16: cobbleventure:generation_1 | N16: region_01; region_02 | P16: #cobblemon:is_freshwater; #cobblemon:is_hills; #cobblemon:is_jungle; #cobblemon:is_temperate; #cobblemon:is_tropical_island | R16: =IF(Q16="",P16,Q16) | S16: #cobblemon:is_freezing | T16: ultra-rare | U16: 6 | V16: 1 | W16: =IF(OR(U16="",V16=""),U16,U16*V16) | X16: 5-31 | Z16: =IF(Y16="",X16,Y16) | AA16: submerged | AF16: True | AJ16: Cobblemon 동일 | AK16: 사용 | AL16: COBBLEVERSE 1.7.42 / DP v31 | AM16: data/cobblemon/spawn_pool_world/0007_squirtle.json | AN16: squirtle-2 | AO16: pokemon | AP16: water | AQ16: {"biomes":["#cobblemon:is_freshwater","#cobblemon:is_hills","#cobblemon:is_jungle","#cobblemon:is_temperate","#cobblemon:is_tropical_island"],"canSeeSky":true} | AR16: {"biomes":["#cobblemon:is_freezing"]}
A17: 0007_squirtle.json::squirtle-3::003 | B17: 사용 | C17: =IF(OR(B17<>AK17,M17<>L17,O17<>"",Q17<>"",V17<>1,Y17<>"",AT17<>""),"수정","원본") | D17: 7 | E17: 꼬부기 | F17: squirtle | G17: squirtle | I17: 1 | K17: 1 | L17: cobbleventure:generation_1 | M17: cobbleventure:generation_1 | N17: region_01; region_02 | P17: #cobblemon:is_freshwater; #cobblemon:is_hills; #cobblemon:is_jungle; #cobblemon:is_temperate; #cobblemon:is_tropical_island | R17: =IF(Q17="",P17,Q17) | S17: #cobblemon:is_freezing | T17: ultra-rare | U17: 6 | V17: 1 | W17: =IF(OR(U17="",V17=""),U17,U17*V17) | X17: 5-31 | Z17: =IF(Y17="",X17,Y17) | AA17: fishing | AF17: True | AJ17: Cobblemon 동일 | AK17: 사용 | AL17: COBBLEVERSE 1.7.42 / DP v31 | AM17: data/cobblemon/spawn_pool_world/0007_squirtle.json | AN17: squirtle-3 | AO17: pokemon | AQ17: {"biomes":["#cobblemon:is_freshwater","#cobblemon:is_hills","#cobblemon:is_jungle","#cobblemon:is_temperate","#cobblemon:is_tropical_island"],"canSeeSky":true} | AR17: {"biomes":["#cobblemon:is_freezing"]}
A18: 0007_squirtle.json::squirtle-4::004 | B18: 사용 | C18: =IF(OR(B18<>AK18,M18<>L18,O18<>"",Q18<>"",V18<>1,Y18<>"",AT18<>""),"수정","원본") | D18: 7 | E18: 꼬부기 | F18: squirtle | G18: squirtle | I18: 1 | K18: 1 | L18: cobbleventure:generation_1 | M18: cobbleventure:generation_1 | N18: region_01; region_02 | P18: #cobblemon:is_freshwater; #cobblemon:is_hills; #cobblemon:is_jungle; #cobblemon:is_temperate; #cobblemon:is_tropical_island | R18: =IF(Q18="",P18,Q18) | S18: #cobblemon:is_freezing | T18: ultra-rare | U18: 6 | V18: 1 | W18: =IF(OR(U18="",V18=""),U18,U18*V18) | X18: 5-31 | Z18: =IF(Y18="",X18,Y18) | AA18: submerged | AE18: sky 8-15 | AF18: False | AJ18: Cobblemon 동일 | AK18: 사용 | AL18: COBBLEVERSE 1.7.42 / DP v31 | AM18: data/cobblemon/spawn_pool_world/0007_squirtle.json | AN18: squirtle-4 | AO18: pokemon | AP18: water | AQ18: {"biomes":["#cobblemon:is_freshwater","#cobblemon:is_hills","#cobblemon:is_jungle","#cobblemon:is_temperate","#cobblemon:is_tropical_island"],"canSeeSky":false,"maxSkyLight":15,"minSkyLight":8} | AR18: {"biomes":["#cobblemon:is_freezing"]}
A19: 0007_squirtle.json::squirtle-5::005 | B19: 사용 | C19: =IF(OR(B19<>AK19,M19<>L19,O19<>"",Q19<>"",V19<>1,Y19<>"",AT19<>""),"수정","원본") | D19: 7 | E19: 꼬부기 | F19: squirtle | G19: squirtle | I19: 1 | K19: 1 | L19: cobbleventure:generation_1 | M19: cobbleventure:generation_1 | N19: region_01; region_02 | P19: #cobblemon:is_freshwater; #cobblemon:is_hills; #cobblemon:is_jungle; #cobblemon:is_temperate; #cobblemon:is_tropical_island | R19: =IF(Q19="",P19,Q19) | S19: #cobblemon:is_freezing | T19: ultra-rare | U19: 6 | V19: 1 | W19: =IF(OR(U19="",V19=""),U19,U19*V19) | X19: 5-31 | Z19: =IF(Y19="",X19,Y19) | AA19: fishing | AE19: sky 8-15 | AF19: False | AJ19: Cobblemon 동일 | AK19: 사용 | AL19: COBBLEVERSE 1.7.42 / DP v31 | AM19: data/cobblemon/spawn_pool_world/0007_squirtle.json | AN19: squirtle-5 | AO19: pokemon | AQ19: {"biomes":["#cobblemon:is_freshwater","#cobblemon:is_hills","#cobblemon:is_jungle","#cobblemon:is_temperate","#cobblemon:is_tropical_island"],"canSeeSky":false,"maxSkyLight":15,"minSkyLight":8} | AR19: {"biomes":["#cobblemon:is_freezing"]}
A20: 0008_wartortle.json::wartortle-1::001 | B20: 사용 | C20: =IF(OR(B20<>AK20,M20<>L20,O20<>"",Q20<>"",V20<>1,Y20<>"",AT20<>""),"수정","원본") | D20: 8 | E20: 어니부기 | F20: wartortle | G20: wartortle | I20: 1 | K20: 1 | L20: cobbleventure:generation_1 | M20: cobbleventure:generation_1 | N20: region_01; region_02 | P20: #cobblemon:is_freshwater; #cobblemon:is_hills; #cobblemon:is_jungle; #cobblemon:is_temperate; #cobblemon:is_tropical_island | R20: =IF(Q20="",P20,Q20) | S20: #cobblemon:is_freezing | T20: ultra-rare | U20: 3.6 | V20: 1 | W20: =IF(OR(U20="",V20=""),U20,U20*V20) | X20: 16-40 | Z20: =IF(Y20="",X20,Y20) | AA20: grounded | AE20: sky 8-15 | AH20: 주변=minecraft:water | AJ20: Cobblemon 동일 | AK20: 사용 | AL20: COBBLEVERSE 1.7.42 / DP v31 | AM20: data/cobblemon/spawn_pool_world/0008_wartortle.json | AN20: wartortle-1 | AO20: pokemon | AP20: natural | AQ20: {"biomes":["#cobblemon:is_freshwater","#cobblemon:is_hills","#cobblemon:is_jungle","#cobblemon:is_temperate","#cobblemon:is_tropical_island"],"maxSkyLight":15,"minSkyLight":8,"neededNearbyBlocks":["minecraft:water"]} | AR20: {"biomes":["#cobblemon:is_freezing"]}
A21: 0008_wartortle.json::wartortle-2::002 | B21: 사용 | C21: =IF(OR(B21<>AK21,M21<>L21,O21<>"",Q21<>"",V21<>1,Y21<>"",AT21<>""),"수정","원본") | D21: 8 | E21: 어니부기 | F21: wartortle | G21: wartortle | I21: 1 | K21: 1 | L21: cobbleventure:generation_1 | M21: cobbleventure:generation_1 | N21: region_01; region_02 | P21: #cobblemon:is_freshwater; #cobblemon:is_hills; #cobblemon:is_jungle; #cobblemon:is_temperate; #cobblemon:is_tropical_island | R21: =IF(Q21="",P21,Q21) | S21: #cobblemon:is_freezing | T21: ultra-rare | U21: 3.6 | V21: 1 | W21: =IF(OR(U21="",V21=""),U21,U21*V21) | X21: 16-40 | Z21: =IF(Y21="",X21,Y21) | AA21: submerged | AF21: True | AJ21: Cobblemon 동일 | AK21: 사용 | AL21: COBBLEVERSE 1.7.42 / DP v31 | AM21: data/cobblemon/spawn_pool_world/0008_wartortle.json | AN21: wartortle-2 | AO21: pokemon | AP21: water | AQ21: {"biomes":["#cobblemon:is_freshwater","#cobblemon:is_hills","#cobblemon:is_jungle","#cobblemon:is_temperate","#cobblemon:is_tropical_island"],"canSeeSky":true} | AR21: {"biomes":["#cobblemon:is_freezing"]}
A22: 0008_wartortle.json::wartortle-3::003 | B22: 사용 | C22: =IF(OR(B22<>AK22,M22<>L22,O22<>"",Q22<>"",V22<>1,Y22<>"",AT22<>""),"수정","원본") | D22: 8 | E22: 어니부기 | F22: wartortle | G22: wartortle | I22: 1 | K22: 1 | L22: cobbleventure:generation_1 | M22: cobbleventure:generation_1 | N22: region_01; region_02 | P22: #cobblemon:is_freshwater; #cobblemon:is_hills; #cobblemon:is_jungle; #cobblemon:is_temperate; #cobblemon:is_tropical_island | R22: =IF(Q22="",P22,Q22) | S22: #cobblemon:is_freezing | T22: ultra-rare | U22: 3.6 | V22: 1 | W22: =IF(OR(U22="",V22=""),U22,U22*V22) | X22: 16-40 | Z22: =IF(Y22="",X22,Y22) | AA22: fishing | AF22: True | AJ22: Cobblemon 동일 | AK22: 사용 | AL22: COBBLEVERSE 1.7.42 / DP v31 | AM22: data/cobblemon/spawn_pool_world/0008_wartortle.json | AN22: wartortle-3 | AO22: pokemon | AQ22: {"biomes":["#cobblemon:is_freshwater","#cobblemon:is_hills","#cobblemon:is_jungle","#cobblemon:is_temperate","#cobblemon:is_tropical_island"],"canSeeSky":true} | AR22: {"biomes":["#cobblemon:is_freezing"]}
A23: 0008_wartortle.json::wartortle-4::004 | B23: 사용 | C23: =IF(OR(B23<>AK23,M23<>L23,O23<>"",Q23<>"",V23<>1,Y23<>"",AT23<>""),"수정","원본") | D23: 8 | E23: 어니부기 | F23: wartortle | G23: wartortle | I23: 1 | K23: 1 | L23: cobbleventure:generation_1 | M23: cobbleventure:generation_1 | N23: region_01; region_02 | P23: #cobblemon:is_freshwater; #cobblemon:is_hills; #cobblemon:is_jungle; #cobblemon:is_temperate; #cobblemon:is_tropical_island | R23: =IF(Q23="",P23,Q23) | S23: #cobblemon:is_freezing | T23: ultra-rare | U23: 3.6 | V23: 1 | W23: =IF(OR(U23="",V23=""),U23,U23*V23) | X23: 16-40 | Z23: =IF(Y23="",X23,Y23) | AA23: submerged | AE23: sky 8-15 | AF23: False | AJ23: Cobblemon 동일 | AK23: 사용 | AL23: COBBLEVERSE 1.7.42 / DP v31 | AM23: data/cobblemon/spawn_pool_world/0008_wartortle.json | AN23: wartortle-4 | AO23: pokemon | AP23: water | AQ23: {"biomes":["#cobblemon:is_freshwater","#cobblemon:is_hills","#cobblemon:is_jungle","#cobblemon:is_temperate","#cobblemon:is_tropical_island"],"canSeeSky":false,"maxSkyLight":15,"minSkyLight":8} | AR23: {"biomes":["#cobblemon:is_freezing"]}
A24: 0008_wartortle.json::wartortle-5::005 | B24: 사용 | C24: =IF(OR(B24<>AK24,M24<>L24,O24<>"",Q24<>"",V24<>1,Y24<>"",AT24<>""),"수정","원본") | D24: 8 | E24: 어니부기 | F24: wartortle | G24: wartortle | I24: 1 | K24: 1 | L24: cobbleventure:generation_1 | M24: cobbleventure:generation_1 | N24: region_01; region_02 | P24: #cobblemon:is_freshwater; #cobblemon:is_hills; #cobblemon:is_jungle; #cobblemon:is_temperate; #cobblemon:is_tropical_island | R24: =IF(Q24="",P24,Q24) | S24: #cobblemon:is_freezing | T24: ultra-rare | U24: 3.6 | V24: 1 | W24: =IF(OR(U24="",V24=""),U24,U24*V24) | X24: 16-40 | Z24: =IF(Y24="",X24,Y24) | AA24: fishing | AE24: sky 8-15 | AF24: False | AJ24: Cobblemon 동일 | AK24: 사용 | AL24: COBBLEVERSE 1.7.42 / DP v31 | AM24: data/cobblemon/spawn_pool_world/0008_wartortle.json | AN24: wartortle-5 | AO24: pokemon | AQ24: {"biomes":["#cobblemon:is_freshwater","#cobblemon:is_hills","#cobblemon:is_jungle","#cobblemon:is_temperate","#cobblemon:is_tropical_island"],"canSeeSky":false,"maxSkyLight":15,"minSkyLight":8} | AR24: {"biomes":["#cobblemon:is_freezing"]}
A25: 0009_blastoise.json::blastoise-1::001 | B25: 사용 | C25: =IF(OR(B25<>AK25,M25<>L25,O25<>"",Q25<>"",V25<>1,Y25<>"",AT25<>""),"수정","원본") | D25: 9 | E25: 거북왕 | F25: blastoise | G25: blastoise | I25: 1 | K25: 1 | L25: cobbleventure:generation_1 | M25: cobbleventure:generation_1 | N25: region_01; region_02 | P25: #cobblemon:is_freshwater; #cobblemon:is_hills; #cobblemon:is_jungle; #cobblemon:is_temperate; #cobblemon:is_tropical_island | R25: =IF(Q25="",P25,Q25) | S25: #cobblemon:is_freezing | T25: ultra-rare | U25: 0.4 | V25: 1 | W25: =IF(OR(U25="",V25=""),U25,U25*V25) | X25: 36-53 | Z25: =IF(Y25="",X25,Y25) | AA25: grounded | AE25: sky 8-15 | AH25: 주변=minecraft:water | AJ25: Cobblemon 동일 | AK25: 사용 | AL25: COBBLEVERSE 1.7.42 / DP v31 | AM25: data/cobblemon/spawn_pool_world/0009_blastoise.json | AN25: blastoise-1 | AO25: pokemon | AP25: natural | AQ25: {"biomes":["#cobblemon:is_freshwater","#cobblemon:is_hills","#cobblemon:is_jungle","#cobblemon:is_temperate","#cobblemon:is_tropical_island"],"maxSkyLight":15,"minSkyLight":8,"neededNearbyBlocks":["minecraft:water"]} | AR25: {"biomes":["#cobblemon:is_freezing"]}
A26: 0009_blastoise.json::blastoise-2::002 | B26: 사용 | C26: =IF(OR(B26<>AK26,M26<>L26,O26<>"",Q26<>"",V26<>1,Y26<>"",AT26<>""),"수정","원본") | D26: 9 | E26: 거북왕 | F26: blastoise | G26: blastoise | I26: 1 | K26: 1 | L26: cobbleventure:generation_1 | M26: cobbleventure:generation_1 | N26: region_01; region_02 | P26: #cobblemon:is_freshwater; #cobblemon:is_hills; #cobblemon:is_jungle; #cobblemon:is_temperate; #cobblemon:is_tropical_island | R26: =IF(Q26="",P26,Q26) | S26: #cobblemon:is_freezing | T26: ultra-rare | U26: 0.4 | V26: 1 | W26: =IF(OR(U26="",V26=""),U26,U26*V26) | X26: 36-53 | Z26: =IF(Y26="",X26,Y26) | AA26: submerged | AF26: True | AJ26: Cobblemon 동일 | AK26: 사용 | AL26: COBBLEVERSE 1.7.42 / DP v31 | AM26: data/cobblemon/spawn_pool_world/0009_blastoise.json | AN26: blastoise-2 | AO26: pokemon | AP26: water | AQ26: {"biomes":["#cobblemon:is_freshwater","#cobblemon:is_hills","#cobblemon:is_jungle","#cobblemon:is_temperate","#cobblemon:is_tropical_island"],"canSeeSky":true} | AR26: {"biomes":["#cobblemon:is_freezing"]}
A27: 0009_blastoise.json::blastoise-3::003 | B27: 사용 | C27: =IF(OR(B27<>AK27,M27<>L27,O27<>"",Q27<>"",V27<>1,Y27<>"",AT27<>""),"수정","원본") | D27: 9 | E27: 거북왕 | F27: blastoise | G27: blastoise | I27: 1 | K27: 1 | L27: cobbleventure:generation_1 | M27: cobbleventure:generation_1 | N27: region_01; region_02 | P27: #cobblemon:is_freshwater; #cobblemon:is_hills; #cobblemon:is_jungle; #cobblemon:is_temperate; #cobblemon:is_tropical_island | R27: =IF(Q27="",P27,Q27) | S27: #cobblemon:is_freezing | T27: ultra-rare | U27: 0.4 | V27: 1 | W27: =IF(OR(U27="",V27=""),U27,U27*V27) | X27: 36-53 | Z27: =IF(Y27="",X27,Y27) | AA27: fishing | AF27: True | AJ27: Cobblemon 동일 | AK27: 사용 | AL27: COBBLEVERSE 1.7.42 / DP v31 | AM27: data/cobblemon/spawn_pool_world/0009_blastoise.json | AN27: blastoise-3 | AO27: pokemon | AQ27: {"biomes":["#cobblemon:is_freshwater","#cobblemon:is_hills","#cobblemon:is_jungle","#cobblemon:is_temperate","#cobblemon:is_tropical_island"],"canSeeSky":true} | AR27: {"biomes":["#cobblemon:is_freezing"]}
A28: 0009_blastoise.json::blastoise-4::004 | B28: 사용 | C28: =IF(OR(B28<>AK28,M28<>L28,O28<>"",Q28<>"",V28<>1,Y28<>"",AT28<>""),"수정","원본") | D28: 9 | E28: 거북왕 | F28: blastoise | G28: blastoise | I28: 1 | K28: 1 | L28: cobbleventure:generation_1 | M28: cobbleventure:generation_1 | N28: region_01; region_02 | P28: #cobblemon:is_freshwater; #cobblemon:is_hills; #cobblemon:is_jungle; #cobblemon:is_temperate; #cobblemon:is_tropical_island | R28: =IF(Q28="",P28,Q28) | S28: #cobblemon:is_freezing | T28: ultra-rare | U28: 0.4 | V28: 1 | W28: =IF(OR(U28="",V28=""),U28,U28*V28) | X28: 36-53 | Z28: =IF(Y28="",X28,Y28) | AA28: submerged | AE28: sky 8-15 | AF28: False | AJ28: Cobblemon 동일 | AK28: 사용 | AL28: COBBLEVERSE 1.7.42 / DP v31 | AM28: data/cobblemon/spawn_pool_world/0009_blastoise.json | AN28: blastoise-4 | AO28: pokemon | AP28: water | AQ28: {"biomes":["#cobblemon:is_freshwater","#cobblemon:is_hills","#cobblemon:is_jungle","#cobblemon:is_temperate","#cobblemon:is_tropical_island"],"canSeeSky":false,"maxSkyLight":15,"minSkyLight":8} | AR28: {"biomes":["#cobblemon:is_freezing"]}
A29: 0009_blastoise.json::blastoise-5::005 | B29: 사용 | C29: =IF(OR(B29<>AK29,M29<>L29,O29<>"",Q29<>"",V29<>1,Y29<>"",AT29<>""),"수정","원본") | D29: 9 | E29: 거북왕 | F29: blastoise | G29: blastoise | I29: 1 | K29: 1 | L29: cobbleventure:generation_1 | M29: cobbleventure:generation_1 | N29: region_01; region_02 | P29: #cobblemon:is_freshwater; #cobblemon:is_hills; #cobblemon:is_jungle; #cobblemon:is_temperate; #cobblemon:is_tropical_island | R29: =IF(Q29="",P29,Q29) | S29: #cobblemon:is_freezing | T29: ultra-rare | U29: 0.4 | V29: 1 | W29: =IF(OR(U29="",V29=""),U29,U29*V29) | X29: 36-53 | Z29: =IF(Y29="",X29,Y29) | AA29: fishing | AE29: sky 8-15 | AF29: False | AJ29: Cobblemon 동일 | AK29: 사용 | AL29: COBBLEVERSE 1.7.42 / DP v31 | AM29: data/cobblemon/spawn_pool_world/0009_blastoise.json | AN29: blastoise-5 | AO29: pokemon | AQ29: {"biomes":["#cobblemon:is_freshwater","#cobblemon:is_hills","#cobblemon:is_jungle","#cobblemon:is_temperate","#cobblemon:is_tropical_island"],"canSeeSky":false,"maxSkyLight":15,"minSkyLight":8} | AR29: {"biomes":["#cobblemon:is_freezing"]}
A30: 0010_caterpie.json::caterpie-1::001 | B30: 사용 | C30: =IF(OR(B30<>AK30,M30<>L30,O30<>"",Q30<>"",V30<>1,Y30<>"",AT30<>""),"수정","원본") | D30: 10 | E30: 캐터피 | F30: caterpie | G30: caterpie | I30: 1 | K30: 1 | L30: cobbleventure:generation_1 | M30: cobbleventure:generation_1 | N30: region_01 | P30: #cobblemon:is_forest; #cobblemon:is_plains; aether:skyroot_forest; aether:skyroot_woodland | R30: =IF(Q30="",P30,Q30) | S30: #cobblemon:is_freezing; #cobblemon:is_spooky | T30: common | U30: 7 | V30: 1 | W30: =IF(OR(U30="",V30=""),U30,U30*V30) | X30: 1-20 | Z30: =IF(Y30="",X30,Y30) | AA30: grounded | AE30: sky 8-15 | AJ30: Cobblemon 동일 | AK30: 사용 | AL30: COBBLEVERSE 1.7.42 / DP v31 | AM30: data/cobblemon/spawn_pool_world/0010_caterpie.json | AN30: caterpie-1 | AO30: pokemon | AP30: natural; foliage; treetop | AQ30: {"biomes":["#cobblemon:is_forest","#cobblemon:is_plains","aether:skyroot_forest","aether:skyroot_woodland"],"maxSkyLight":15,"minSkyLight":8} | AR30: {"biomes":["#cobblemon:is_freezing","#cobblemon:is_spooky"]}
A31: 0010_caterpie.json::caterpie-valencian-2::002 | B31: 사용 | C31: =IF(OR(B31<>AK31,M31<>L31,O31<>"",Q31<>"",V31<>1,Y31<>"",AT31<>""),"수정","원본") | D31: 10 | E31: 캐터피 | F31: caterpie | G31: caterpie valencian | H31: valencian | I31: 1 | K31: 1 | L31: cobbleventure:generation_1 | M31: cobbleventure:generation_1 | P31: #cobblemon:is_jungle; #cobblemon:is_tropical_island | R31: =IF(Q31="",P31,Q31) | T31: common | U31: 7 | V31: 1 | W31: =IF(OR(U31="",V31=""),U31,U31*V31) | X31: 1-20 | Z31: =IF(Y31="",X31,Y31) | AA31: grounded | AE31: sky 8-15 | AJ31: Cobblemon 동일 | AK31: 사용 | AL31: COBBLEVERSE 1.7.42 / DP v31 | AM31: data/cobblemon/spawn_pool_world/0010_caterpie.json | AN31: caterpie-valencian-2 | AO31: pokemon | AP31: natural; treetop | AQ31: {"biomes":["#cobblemon:is_jungle","#cobblemon:is_tropical_island"],"maxSkyLight":15,"minSkyLight":8}
A32: 0010_caterpie.json::caterpie-valencian-3::003 | B32: 사용 | C32: =IF(OR(B32<>AK32,M32<>L32,O32<>"",Q32<>"",V32<>1,Y32<>"",AT32<>""),"수정","원본") | D32: 10 | E32: 캐터피 | F32: caterpie | G32: caterpie valencian | H32: valencian | I32: 1 | K32: 1 | L32: cobbleventure:generation_1 | M32: cobbleventure:generation_1 | P32: the_bumblezone:floral_meadow | R32: =IF(Q32="",P32,Q32) | T32: common | U32: 4.5 | V32: 1 | W32: =IF(OR(U32="",V32=""),U32,U32*V32) | X32: 1-20 | Z32: =IF(Y32="",X32,Y32) | AA32: grounded | AJ32: Cobblemon 동일 | AK32: 사용 | AL32: COBBLEVERSE 1.7.42 / DP v31 | AM32: data/cobblemon/spawn_pool_world/0010_caterpie.json | AN32: caterpie-valencian-3 | AO32: pokemon | AQ32: {"biomes":["the_bumblezone:floral_meadow"]} | AR32: {"structures":["#the_bumblezone:sempiternal_sanctums"]}
A33: 0011_metapod.json::metapod-1::001 | B33: 사용 | C33: =IF(OR(B33<>AK33,M33<>L33,O33<>"",Q33<>"",V33<>1,Y33<>"",AT33<>""),"수정","원본") | D33: 11 | E33: 단데기 | F33: metapod | G33: metapod | I33: 1 | K33: 1 | L33: cobbleventure:generation_1 | M33: cobbleventure:generation_1 | N33: region_01 | P33: #cobblemon:is_forest; #cobblemon:is_plains; aether:skyroot_forest; aether:skyroot_woodland | R33: =IF(Q33="",P33,Q33) | S33: #cobblemon:is_freezing; #cobblemon:is_spooky | T33: common | U33: 2 | V33: 1 | W33: =IF(OR(U33="",V33=""),U33,U33*V33) | X33: 7-21 | Z33: =IF(Y33="",X33,Y33) | AA33: grounded | AE33: sky 8-15 | AJ33: Cobblemon 동일 | AK33: 사용 | AL33: COBBLEVERSE 1.7.42 / DP v31 | AM33: data/cobblemon/spawn_pool_world/0011_metapod.json | AN33: metapod-1 | AO33: pokemon | AP33: natural; foliage; treetop | AQ33: {"biomes":["#cobblemon:is_forest","#cobblemon:is_plains","aether:skyroot_forest","aether:skyroot_woodland"],"maxSkyLight":15,"minSkyLight":8} | AR33: {"biomes":["#cobblemon:is_freezing","#cobblemon:is_spooky"]}
A34: 0011_metapod.json::metapod-valencian-2::002 | B34: 사용 | C34: =IF(OR(B34<>AK34,M34<>L34,O34<>"",Q34<>"",V34<>1,Y34<>"",AT34<>""),"수정","원본") | D34: 11 | E34: 단데기 | F34: metapod | G34: metapod valencian | H34: valencian | I34: 1 | K34: 1 | L34: cobbleventure:generation_1 | M34: cobbleventure:generation_1 | P34: #cobblemon:is_jungle; #cobblemon:is_tropical_island | R34: =IF(Q34="",P34,Q34) | T34: common | U34: 2 | V34: 1 | W34: =IF(OR(U34="",V34=""),U34,U34*V34) | X34: 7-21 | Z34: =IF(Y34="",X34,Y34) | AA34: grounded | AE34: sky 8-15 | AJ34: Cobblemon 동일 | AK34: 사용 | AL34: COBBLEVERSE 1.7.42 / DP v31 | AM34: data/cobblemon/spawn_pool_world/0011_metapod.json | AN34: metapod-valencian-2 | AO34: pokemon | AP34: natural; treetop | AQ34: {"biomes":["#cobblemon:is_jungle","#cobblemon:is_tropical_island"],"maxSkyLight":15,"minSkyLight":8}
A35: 0011_metapod.json::metapod-valencian-3::003 | B35: 사용 | C35: =IF(OR(B35<>AK35,M35<>L35,O35<>"",Q35<>"",V35<>1,Y35<>"",AT35<>""),"수정","원본") | D35: 11 | E35: 단데기 | F35: metapod | G35: metapod valencian | H35: valencian | I35: 1 | K35: 1 | L35: cobbleventure:generation_1 | M35: cobbleventure:generation_1 | P35: the_bumblezone:floral_meadow | R35: =IF(Q35="",P35,Q35) | T35: common | U35: 1 | V35: 1 | W35: =IF(OR(U35="",V35=""),U35,U35*V35) | X35: 7-21 | Z35: =IF(Y35="",X35,Y35) | AA35: grounded | AJ35: Cobblemon 동일 | AK35: 사용 | AL35: COBBLEVERSE 1.7.42 / DP v31 | AM35: data/cobblemon/spawn_pool_world/0011_metapod.json | AN35: metapod-valencian-3 | AO35: pokemon | AQ35: {"biomes":["the_bumblezone:floral_meadow"]} | AR35: {"structures":["#the_bumblezone:sempiternal_sanctums"]}
A36: 0012_butterfree.json::butterfree-1::001 | B36: 사용 | C36: =IF(OR(B36<>AK36,M36<>L36,O36<>"",Q36<>"",V36<>1,Y36<>"",AT36<>""),"수정","원본") | D36: 12 | E36: 버터플 | F36: butterfree | G36: butterfree | I36: 1 | K36: 1 | L36: cobbleventure:generation_1 | M36: cobbleventure:generation_1 | N36: region_01 | P36: #cobblemon:is_temperate | R36: =IF(Q36="",P36,Q36) | S36: #cobblemon:is_floral; #cobblemon:is_freezing; #cobblemon:is_spooky | T36: common | U36: 1 | V36: 1 | W36: =IF(OR(U36="",V36=""),U36,U36*V36) | X36: 10-40 | Z36: =IF(Y36="",X36,Y36) | AA36: grounded | AB36: day | AE36: sky 8-15 | AJ36: Cobblemon 동일 | AK36: 사용 | AL36: COBBLEVERSE 1.7.42 / DP v31 | AM36: data/cobblemon/spawn_pool_world/0012_butterfree.json | AN36: butterfree-1 | AO36: pokemon | AP36: natural | AQ36: {"biomes":["#cobblemon:is_temperate"],"maxSkyLight":15,"minSkyLight":8,"timeRange":"day"} | AR36: {"biomes":["#cobblemon:is_floral","#cobblemon:is_freezing","#cobblemon:is_spooky"]}
A37: 0012_butterfree.json::butterfree-2::002 | B37: 사용 | C37: =IF(OR(B37<>AK37,M37<>L37,O37<>"",Q37<>"",V37<>1,Y37<>"",AT37<>""),"수정","원본") | D37: 12 | E37: 버터플 | F37: butterfree | G37: butterfree | I37: 1 | K37: 1 | L37: cobbleventure:generation_1 | M37: cobbleventure:generation_1 | P37: #cobblemon:is_floral | R37: =IF(Q37="",P37,Q37) | T37: common | U37: 10 | V37: 1 | W37: =IF(OR(U37="",V37=""),U37,U37*V37) | X37: 10-40 | Z37: =IF(Y37="",X37,Y37) | AA37: grounded | AB37: day | AE37: sky 8-15 | AJ37: Cobblemon 동일 | AK37: 사용 | AL37: COBBLEVERSE 1.7.42 / DP v31 | AM37: data/cobblemon/spawn_pool_world/0012_butterfree.json | AN37: butterfree-2 | AO37: pokemon | AP37: natural | AQ37: {"biomes":["#cobblemon:is_floral"],"maxSkyLight":15,"minSkyLight":8,"timeRange":"day"}
A38: 0012_butterfree.json::butterfree-3::003 | B38: 사용 | C38: =IF(OR(B38<>AK38,M38<>L38,O38<>"",Q38<>"",V38<>1,Y38<>"",AT38<>""),"수정","원본") | D38: 12 | E38: 버터플 | F38: butterfree | G38: butterfree | I38: 1 | K38: 1 | L38: cobbleventure:generation_1 | M38: cobbleventure:generation_1 | P38: #aether:is_aether | R38: =IF(Q38="",P38,Q38) | T38: common | U38: 1 | V38: 1 | W38: =IF(OR(U38="",V38=""),U38,U38*V38) | X38: 10-40 | Z38: =IF(Y38="",X38,Y38) | AA38: grounded | AE38: sky 8-15 | AJ38: Cobblemon 동일 | AK38: 사용 | AL38: COBBLEVERSE 1.7.42 / DP v31 | AM38: data/cobblemon/spawn_pool_world/0012_butterfree.json | AN38: butterfree-3 | AO38: pokemon | AP38: natural | AQ38: {"biomes":["#aether:is_aether"],"maxSkyLight":15,"minSkyLight":8}
A39: 0012_butterfree.json::butterfree-valencian-4::004 | B39: 사용 | C39: =IF(OR(B39<>AK39,M39<>L39,O39<>"",Q39<>"",V39<>1,Y39<>"",AT39<>""),"수정","원본") | D39: 12 | E39: 버터플 | F39: butterfree | G39: butterfree valencian | H39: valencian | I39: 1 | K39: 1 | L39: cobbleventure:generation_1 | M39: cobbleventure:generation_1 | P39: #cobblemon:is_jungle; #cobblemon:is_tropical_island | R39: =IF(Q39="",P39,Q39) | T39: common | U39: 1 | V39: 1 | W39: =IF(OR(U39="",V39=""),U39,U39*V39) | X39: 10-40 | Z39: =IF(Y39="",X39,Y39) | AA39: grounded | AB39: day | AE39: sky 8-15 | AJ39: Cobblemon 동일 | AK39: 사용 | AL39: COBBLEVERSE 1.7.42 / DP v31 | AM39: data/cobblemon/spawn_pool_world/0012_butterfree.json | AN39: butterfree-valencian-4 | AO39: pokemon | AP39: natural | AQ39: {"biomes":["#cobblemon:is_jungle","#cobblemon:is_tropical_island"],"maxSkyLight":15,"minSkyLight":8,"timeRange":"day"}
A40: 0012_butterfree.json::butterfree-valencian-5::005 | B40: 사용 | C40: =IF(OR(B40<>AK40,M40<>L40,O40<>"",Q40<>"",V40<>1,Y40<>"",AT40<>""),"수정","원본") | D40: 12 | E40: 버터플 | F40: butterfree | G40: butterfree valencian | H40: valencian | I40: 1 | K40: 1 | L40: cobbleventure:generation_1 | M40: cobbleventure:generation_1 | P40: the_bumblezone:floral_meadow | R40: =IF(Q40="",P40,Q40) | T40: common | U40: 5 | V40: 1 | W40: =IF(OR(U40="",V40=""),U40,U40*V40) | X40: 10-40 | Z40: =IF(Y40="",X40,Y40) | AA40: grounded | AJ40: Cobblemon 동일 | AK40: 사용 | AL40: COBBLEVERSE 1.7.42 / DP v31 | AM40: data/cobblemon/spawn_pool_world/0012_butterfree.json | AN40: butterfree-valencian-5 | AO40: pokemon | AQ40: {"biomes":["the_bumblezone:floral_meadow"]} | AR40: {"structures":["#the_bumblezone:sempiternal_sanctums"]}
A41: 0013_weedle.json::weedle-1::001 | B41: 사용 | C41: =IF(OR(B41<>AK41,M41<>L41,O41<>"",Q41<>"",V41<>1,Y41<>"",AT41<>""),"수정","원본") | D41: 13 | E41: 뿔충이 | F41: weedle | G41: weedle | I41: 1 | K41: 1 | L41: cobbleventure:generation_1 | M41: cobbleventure:generation_1 | N41: region_01 | P41: #cobblemon:is_forest; #cobblemon:is_jungle; aether:skyroot_forest; aether:skyroot_woodland | R41: =IF(Q41="",P41,Q41) | S41: #cobblemon:is_freezing | T41: common | U41: 7 | V41: 1 | W41: =IF(OR(U41="",V41=""),U41,U41*V41) | X41: 1-20 | Z41: =IF(Y41="",X41,Y41) | AA41: grounded | AE41: sky 8-15 | AJ41: Cobblemon 동일 | AK41: 사용 | AL41: COBBLEVERSE 1.7.42 / DP v31 | AM41: data/cobblemon/spawn_pool_world/0013_weedle.json | AN41: weedle-1 | AO41: pokemon | AP41: natural; treetop | AQ41: {"biomes":["#cobblemon:is_forest","#cobblemon:is_jungle","aether:skyroot_forest","aether:skyroot_woodland"],"maxSkyLight":15,"minSkyLight":8} | AR41: {"biomes":["#cobblemon:is_freezing"]}
...

Sheet 포켓몬_요약
A1: 포켓몬 1,025종 구현·자연 스폰 요약
A2: Cobblemon 구현 여부와 COBBLEVERSE 자연 스폰 보완 여부를 분리했습니다. 자연 스폰 파일이 없는 8종은 진화·복원 등 별도 획득 대상일 수 있습니다.
A4: 덱스번호 | B4: 한글명 | C4: 영문ID | D4: 영문명 | E4: 기본세대 | F4: Cobblemon세대폴더 | G4: 타입1 | H4: 타입2 | I4: Cobblemon구현 | J4: Cobblemon스폰파일 | K4: COBBLEVERSE스폰파일 | L4: 원본상태 | M4: 전체스폰수 | N4: 사용스폰수 | O4: 원본바이옴수 | P4: 원본바이옴목록 | Q4: 희귀도 | R4: 지역후보 | S4: 기본차원 | T4: 자연스폰상태 | U4: 비고
A5: 1 | B5: 이상해씨 | C5: bulbasaur | D5: Bulbasaur | E5: 1 | F5: generation1 | G5: grass | H5: poison | I5: 예 | J5: 예 | K5: 예 | L5: Cobblemon 동일 | M5: =COUNTIF('스폰_편집'!$D$5:$D$3125,A5) | N5: =COUNTIFS('스폰_편집'!$D$5:$D$3125,A5,'스폰_편집'!$B$5:$B$3125,"사용") | O5: 2 | P5: #cobblemon:is_jungle; #cobblemon:is_tropical_island | Q5: ultra-rare | S5: cobbleventure:generation_1 | T5: =IF(M5=0,"없음",IF(N5=0,"전부 제외","사용"))
A6: 2 | B6: 이상해풀 | C6: ivysaur | D6: Ivysaur | E6: 1 | F6: generation1 | G6: grass | H6: poison | I6: 예 | J6: 예 | K6: 예 | L6: Cobblemon 동일 | M6: =COUNTIF('스폰_편집'!$D$5:$D$3125,A6) | N6: =COUNTIFS('스폰_편집'!$D$5:$D$3125,A6,'스폰_편집'!$B$5:$B$3125,"사용") | O6: 2 | P6: #cobblemon:is_jungle; #cobblemon:is_tropical_island | Q6: ultra-rare | S6: cobbleventure:generation_1 | T6: =IF(M6=0,"없음",IF(N6=0,"전부 제외","사용"))
A7: 3 | B7: 이상해꽃 | C7: venusaur | D7: Venusaur | E7: 1 | F7: generation1 | G7: grass | H7: poison | I7: 예 | J7: 예 | K7: 예 | L7: Cobblemon 동일 | M7: =COUNTIF('스폰_편집'!$D$5:$D$3125,A7) | N7: =COUNTIFS('스폰_편집'!$D$5:$D$3125,A7,'스폰_편집'!$B$5:$B$3125,"사용") | O7: 2 | P7: #cobblemon:is_jungle; #cobblemon:is_tropical_island | Q7: ultra-rare | S7: cobbleventure:generation_1 | T7: =IF(M7=0,"없음",IF(N7=0,"전부 제외","사용"))
A8: 4 | B8: 파이리 | C8: charmander | D8: Charmander | E8: 1 | F8: generation1 | G8: fire | I8: 예 | J8: 예 | K8: 예 | L8: Cobblemon 동일 | M8: =COUNTIF('스폰_편집'!$D$5:$D$3125,A8) | N8: =COUNTIFS('스폰_편집'!$D$5:$D$3125,A8,'스폰_편집'!$B$5:$B$3125,"사용") | O8: 3 | P8: #cobblemon:is_hills; #cobblemon:is_volcanic; #cobblemon:nether/is_basalt | Q8: ultra-rare | S8: cobbleventure:generation_1 | T8: =IF(M8=0,"없음",IF(N8=0,"전부 제외","사용"))
A9: 5 | B9: 리자드 | C9: charmeleon | D9: Charmeleon | E9: 1 | F9: generation1 | G9: fire | I9: 예 | J9: 예 | K9: 예 | L9: Cobblemon 동일 | M9: =COUNTIF('스폰_편집'!$D$5:$D$3125,A9) | N9: =COUNTIFS('스폰_편집'!$D$5:$D$3125,A9,'스폰_편집'!$B$5:$B$3125,"사용") | O9: 3 | P9: #cobblemon:is_hills; #cobblemon:is_volcanic; #cobblemon:nether/is_basalt | Q9: ultra-rare | S9: cobbleventure:generation_1 | T9: =IF(M9=0,"없음",IF(N9=0,"전부 제외","사용"))
A10: 6 | B10: 리자몽 | C10: charizard | D10: Charizard | E10: 1 | F10: generation1 | G10: fire | H10: flying | I10: 예 | J10: 예 | K10: 예 | L10: Cobblemon 동일 | M10: =COUNTIF('스폰_편집'!$D$5:$D$3125,A10) | N10: =COUNTIFS('스폰_편집'!$D$5:$D$3125,A10,'스폰_편집'!$B$5:$B$3125,"사용") | O10: 3 | P10: #cobblemon:is_hills; #cobblemon:is_volcanic; #cobblemon:nether/is_basalt | Q10: ultra-rare | S10: cobbleventure:generation_1 | T10: =IF(M10=0,"없음",IF(N10=0,"전부 제외","사용"))
A11: 7 | B11: 꼬부기 | C11: squirtle | D11: Squirtle | E11: 1 | F11: generation1 | G11: water | I11: 예 | J11: 예 | K11: 예 | L11: Cobblemon 동일 | M11: =COUNTIF('스폰_편집'!$D$5:$D$3125,A11) | N11: =COUNTIFS('스폰_편집'!$D$5:$D$3125,A11,'스폰_편집'!$B$5:$B$3125,"사용") | O11: 5 | P11: #cobblemon:is_freshwater; #cobblemon:is_hills; #cobblemon:is_jungle; #cobblemon:is_temperate; #cobblemon:is_tropical_island | Q11: ultra-rare | R11: region_01; region_02 | S11: cobbleventure:generation_1 | T11: =IF(M11=0,"없음",IF(N11=0,"전부 제외","사용"))
A12: 8 | B12: 어니부기 | C12: wartortle | D12: Wartortle | E12: 1 | F12: generation1 | G12: water | I12: 예 | J12: 예 | K12: 예 | L12: Cobblemon 동일 | M12: =COUNTIF('스폰_편집'!$D$5:$D$3125,A12) | N12: =COUNTIFS('스폰_편집'!$D$5:$D$3125,A12,'스폰_편집'!$B$5:$B$3125,"사용") | O12: 5 | P12: #cobblemon:is_freshwater; #cobblemon:is_hills; #cobblemon:is_jungle; #cobblemon:is_temperate; #cobblemon:is_tropical_island | Q12: ultra-rare | R12: region_01; region_02 | S12: cobbleventure:generation_1 | T12: =IF(M12=0,"없음",IF(N12=0,"전부 제외","사용"))
A13: 9 | B13: 거북왕 | C13: blastoise | D13: Blastoise | E13: 1 | F13: generation1 | G13: water | I13: 예 | J13: 예 | K13: 예 | L13: Cobblemon 동일 | M13: =COUNTIF('스폰_편집'!$D$5:$D$3125,A13) | N13: =COUNTIFS('스폰_편집'!$D$5:$D$3125,A13,'스폰_편집'!$B$5:$B$3125,"사용") | O13: 5 | P13: #cobblemon:is_freshwater; #cobblemon:is_hills; #cobblemon:is_jungle; #cobblemon:is_temperate; #cobblemon:is_tropical_island | Q13: ultra-rare | R13: region_01; region_02 | S13: cobbleventure:generation_1 | T13: =IF(M13=0,"없음",IF(N13=0,"전부 제외","사용"))
A14: 10 | B14: 캐터피 | C14: caterpie | D14: Caterpie | E14: 1 | F14: generation1 | G14: bug | I14: 예 | J14: 예 | K14: 예 | L14: Cobblemon 동일 | M14: =COUNTIF('스폰_편집'!$D$5:$D$3125,A14) | N14: =COUNTIFS('스폰_편집'!$D$5:$D$3125,A14,'스폰_편집'!$B$5:$B$3125,"사용") | O14: 7 | P14: #cobblemon:is_forest; #cobblemon:is_jungle; #cobblemon:is_plains; #cobblemon:is_tropical_island; aether:skyroot_forest; aether:skyroot_woodland; the_bumblezone:floral_meadow | Q14: common | R14: region_01 | S14: cobbleventure:generation_1 | T14: =IF(M14=0,"없음",IF(N14=0,"전부 제외","사용"))
A15: 11 | B15: 단데기 | C15: metapod | D15: Metapod | E15: 1 | F15: generation1 | G15: bug | I15: 예 | J15: 예 | K15: 예 | L15: Cobblemon 동일 | M15: =COUNTIF('스폰_편집'!$D$5:$D$3125,A15) | N15: =COUNTIFS('스폰_편집'!$D$5:$D$3125,A15,'스폰_편집'!$B$5:$B$3125,"사용") | O15: 7 | P15: #cobblemon:is_forest; #cobblemon:is_jungle; #cobblemon:is_plains; #cobblemon:is_tropical_island; aether:skyroot_forest; aether:skyroot_woodland; the_bumblezone:floral_meadow | Q15: common | R15: region_01 | S15: cobbleventure:generation_1 | T15: =IF(M15=0,"없음",IF(N15=0,"전부 제외","사용"))
A16: 12 | B16: 버터플 | C16: butterfree | D16: Butterfree | E16: 1 | F16: generation1 | G16: bug | H16: flying | I16: 예 | J16: 예 | K16: 예 | L16: Cobblemon 동일 | M16: =COUNTIF('스폰_편집'!$D$5:$D$3125,A16) | N16: =COUNTIFS('스폰_편집'!$D$5:$D$3125,A16,'스폰_편집'!$B$5:$B$3125,"사용") | O16: 6 | P16: #aether:is_aether; #cobblemon:is_floral; #cobblemon:is_jungle; #cobblemon:is_temperate; #cobblemon:is_tropical_island; the_bumblezone:floral_meadow | Q16: common | R16: region_01 | S16: cobbleventure:generation_1 | T16: =IF(M16=0,"없음",IF(N16=0,"전부 제외","사용"))
A17: 13 | B17: 뿔충이 | C17: weedle | D17: Weedle | E17: 1 | F17: generation1 | G17: bug | H17: poison | I17: 예 | J17: 예 | K17: 예 | L17: Cobblemon 동일 | M17: =COUNTIF('스폰_편집'!$D$5:$D$3125,A17) | N17: =COUNTIFS('스폰_편집'!$D$5:$D$3125,A17,'스폰_편집'!$B$5:$B$3125,"사용") | O17: 5 | P17: #cobblemon:is_forest; #cobblemon:is_jungle; #the_bumblezone:the_bumblezone; aether:skyroot_forest; aether:skyroot_woodland | Q17: common | R17: region_01 | S17: cobbleventure:generation_1 | T17: =IF(M17=0,"없음",IF(N17=0,"전부 제외","사용"))
A18: 14 | B18: 딱충이 | C18: kakuna | D18: Kakuna | E18: 1 | F18: generation1 | G18: bug | H18: poison | I18: 예 | J18: 예 | K18: 예 | L18: Cobblemon 동일 | M18: =COUNTIF('스폰_편집'!$D$5:$D$3125,A18) | N18: =COUNTIFS('스폰_편집'!$D$5:$D$3125,A18,'스폰_편집'!$B$5:$B$3125,"사용") | O18: 5 | P18: #cobblemon:is_forest; #cobblemon:is_jungle; #the_bumblezone:the_bumblezone; aether:skyroot_forest; aether:skyroot_woodland | Q18: common | R18: region_01 | S18: cobbleventure:generation_1 | T18: =IF(M18=0,"없음",IF(N18=0,"전부 제외","사용"))
A19: 15 | B19: 독침붕 | C19: beedrill | D19: Beedrill | E19: 1 | F19: generation1 | G19: bug | H19: poison | I19: 예 | J19: 예 | K19: 예 | L19: Cobblemon 동일 | M19: =COUNTIF('스폰_편집'!$D$5:$D$3125,A19) | N19: =COUNTIFS('스폰_편집'!$D$5:$D$3125,A19,'스폰_편집'!$B$5:$B$3125,"사용") | O19: 5 | P19: #cobblemon:is_forest; #cobblemon:is_jungle; #the_bumblezone:the_bumblezone; aether:skyroot_forest; aether:skyroot_woodland | Q19: common | R19: region_01 | S19: cobbleventure:generation_1 | T19: =IF(M19=0,"없음",IF(N19=0,"전부 제외","사용"))
A20: 16 | B20: 구구 | C20: pidgey | D20: Pidgey | E20: 1 | F20: generation1 | G20: normal | H20: flying | I20: 예 | J20: 예 | K20: 예 | L20: Cobblemon 동일 | M20: =COUNTIF('스폰_편집'!$D$5:$D$3125,A20) | N20: =COUNTIFS('스폰_편집'!$D$5:$D$3125,A20,'스폰_편집'!$B$5:$B$3125,"사용") | O20: 4 | P20: #cobblemon:is_sky; #cobblemon:is_temperate; aether:skyroot_forest; aether:skyroot_woodland | Q20: common | R20: region_01 | S20: cobbleventure:generation_1 | T20: =IF(M20=0,"없음",IF(N20=0,"전부 제외","사용"))
A21: 17 | B21: 피죤 | C21: pidgeotto | D21: Pidgeotto | E21: 1 | F21: generation1 | G21: normal | H21: flying | I21: 예 | J21: 예 | K21: 예 | L21: Cobblemon 동일 | M21: =COUNTIF('스폰_편집'!$D$5:$D$3125,A21) | N21: =COUNTIFS('스폰_편집'!$D$5:$D$3125,A21,'스폰_편집'!$B$5:$B$3125,"사용") | O21: 4 | P21: #cobblemon:is_sky; #cobblemon:is_temperate; aether:skyroot_forest; aether:skyroot_woodland | Q21: common | R21: region_01 | S21: cobbleventure:generation_1 | T21: =IF(M21=0,"없음",IF(N21=0,"전부 제외","사용"))
A22: 18 | B22: 피죤투 | C22: pidgeot | D22: Pidgeot | E22: 1 | F22: generation1 | G22: normal | H22: flying | I22: 예 | J22: 예 | K22: 예 | L22: Cobblemon 동일 | M22: =COUNTIF('스폰_편집'!$D$5:$D$3125,A22) | N22: =COUNTIFS('스폰_편집'!$D$5:$D$3125,A22,'스폰_편집'!$B$5:$B$3125,"사용") | O22: 4 | P22: #cobblemon:is_sky; #cobblemon:is_temperate; aether:skyroot_forest; aether:skyroot_woodland | Q22: common | R22: region_01 | S22: cobbleventure:generation_1 | T22: =IF(M22=0,"없음",IF(N22=0,"전부 제외","사용"))
A23: 19 | B23: 꼬렛 | C23: rattata | D23: Rattata | E23: 1 | F23: generation1 | G23: normal | I23: 예 | J23: 예 | K23: 예 | L23: Cobblemon 동일 | M23: =COUNTIF('스폰_편집'!$D$5:$D$3125,A23) | N23: =COUNTIFS('스폰_편집'!$D$5:$D$3125,A23,'스폰_편집'!$B$5:$B$3125,"사용") | O23: 3 | P23: #cobblemon:is_grassland; #cobblemon:is_overworld; #cobblemon:is_spooky | Q23: common; uncommon | R23: region_01; region_02 | S23: cobbleventure:generation_1 | T23: =IF(M23=0,"없음",IF(N23=0,"전부 제외","사용"))
A24: 20 | B24: 레트라 | C24: raticate | D24: Raticate | E24: 1 | F24: generation1 | G24: normal | I24: 예 | J24: 예 | K24: 예 | L24: Cobblemon 동일 | M24: =COUNTIF('스폰_편집'!$D$5:$D$3125,A24) | N24: =COUNTIFS('스폰_편집'!$D$5:$D$3125,A24,'스폰_편집'!$B$5:$B$3125,"사용") | O24: 3 | P24: #cobblemon:is_grassland; #cobblemon:is_overworld; #cobblemon:is_spooky | Q24: common; uncommon | R24: region_01; region_02 | S24: cobbleventure:generation_1 | T24: =IF(M24=0,"없음",IF(N24=0,"전부 제외","사용"))
A25: 21 | B25: 깨비참 | C25: spearow | D25: Spearow | E25: 1 | F25: generation1 | G25: normal | H25: flying | I25: 예 | J25: 예 | K25: 예 | L25: Cobblemon 동일 | M25: =COUNTIF('스폰_편집'!$D$5:$D$3125,A25) | N25: =COUNTIFS('스폰_편집'!$D$5:$D$3125,A25,'스폰_편집'!$B$5:$B$3125,"사용") | O25: 3 | P25: #cobblemon:is_badlands; #cobblemon:is_savanna; #cobblemon:is_sky | Q25: common | S25: cobbleventure:generation_1 | T25: =IF(M25=0,"없음",IF(N25=0,"전부 제외","사용"))
A26: 22 | B26: 깨비드릴조 | C26: fearow | D26: Fearow | E26: 1 | F26: generation1 | G26: normal | H26: flying | I26: 예 | J26: 예 | K26: 예 | L26: Cobblemon 동일 | M26: =COUNTIF('스폰_편집'!$D$5:$D$3125,A26) | N26: =COUNTIFS('스폰_편집'!$D$5:$D$3125,A26,'스폰_편집'!$B$5:$B$3125,"사용") | O26: 3 | P26: #cobblemon:is_badlands; #cobblemon:is_savanna; #cobblemon:is_sky | Q26: common | S26: cobbleventure:generation_1 | T26: =IF(M26=0,"없음",IF(N26=0,"전부 제외","사용"))
A27: 23 | B27: 아보 | C27: ekans | D27: Ekans | E27: 1 | F27: generation1 | G27: poison | I27: 예 | J27: 예 | K27: 예 | L27: COBBLEVERSE 수정 | M27: =COUNTIF('스폰_편집'!$D$5:$D$3125,A27) | N27: =COUNTIFS('스폰_편집'!$D$5:$D$3125,A27,'스폰_편집'!$B$5:$B$3125,"사용") | O27: 2 | P27: #cobblemon:is_arid; minecraft:deep_dark | Q27: common | R27: region_02 | S27: cobbleventure:generation_1 | T27: =IF(M27=0,"없음",IF(N27=0,"전부 제외","사용"))
A28: 24 | B28: 아보크 | C28: arbok | D28: Arbok | E28: 1 | F28: generation1 | G28: poison | I28: 예 | J28: 예 | K28: 예 | L28: COBBLEVERSE 수정 | M28: =COUNTIF('스폰_편집'!$D$5:$D$3125,A28) | N28: =COUNTIFS('스폰_편집'!$D$5:$D$3125,A28,'스폰_편집'!$B$5:$B$3125,"사용") | O28: 2 | P28: #cobblemon:is_arid; minecraft:deep_dark | Q28: common | R28: region_02 | S28: cobbleventure:generation_1 | T28: =IF(M28=0,"없음",IF(N28=0,"전부 제외","사용"))
A29: 25 | B29: 피카츄 | C29: pikachu | D29: Pikachu | E29: 1 | F29: generation1 | G29: electric | I29: 예 | J29: 예 | K29: 예 | L29: COBBLEVERSE 수정 | M29: =COUNTIF('스폰_편집'!$D$5:$D$3125,A29) | N29: =COUNTIFS('스폰_편집'!$D$5:$D$3125,A29,'스폰_편집'!$B$5:$B$3125,"사용") | O29: 9 | P29: #cobblemon:is_beach; #cobblemon:is_forest; #cobblemon:is_tropical_island; #minecraft:is_badlands; #minecraft:is_jungle; #minecraft:is_savanna; cobbleverse:not_spawn; minecraft:cherry_grove; minecraft:sunflower_plains | Q29: rare; uncommon | R29: region_01 | S29: cobbleventure:generation_1 | T29: =IF(M29=0,"없음",IF(N29=0,"전부 제외","사용"))
A30: 26 | B30: 라이츄 | C30: raichu | D30: Raichu | E30: 1 | F30: generation1 | G30: electric | I30: 예 | J30: 예 | K30: 예 | L30: Cobblemon 동일 | M30: =COUNTIF('스폰_편집'!$D$5:$D$3125,A30) | N30: =COUNTIFS('스폰_편집'!$D$5:$D$3125,A30,'스폰_편집'!$B$5:$B$3125,"사용") | O30: 5 | P30: #cobblemon:is_beach; #cobblemon:is_forest; #cobblemon:is_tropical_island; aether:skyroot_forest; aether:skyroot_woodland | Q30: uncommon | R30: region_01 | S30: cobbleventure:generation_1 | T30: =IF(M30=0,"없음",IF(N30=0,"전부 제외","사용"))
A31: 27 | B31: 모래두지 | C31: sandshrew | D31: Sandshrew | E31: 1 | F31: generation1 | G31: ground | I31: 예 | J31: 예 | K31: 예 | L31: COBBLEVERSE 수정 | M31: =COUNTIF('스폰_편집'!$D$5:$D$3125,A31) | N31: =COUNTIFS('스폰_편집'!$D$5:$D$3125,A31,'스폰_편집'!$B$5:$B$3125,"사용") | O31: 2 | P31: #cobblemon:is_desert; #cobblemon:is_glacial | Q31: common; uncommon | R31: region_02 | S31: cobbleventure:generation_1 | T31: =IF(M31=0,"없음",IF(N31=0,"전부 제외","사용"))
A32: 28 | B32: 고지 | C32: sandslash | D32: Sandslash | E32: 1 | F32: generation1 | G32: ground | I32: 예 | J32: 예 | K32: 예 | L32: COBBLEVERSE 수정 | M32: =COUNTIF('스폰_편집'!$D$5:$D$3125,A32) | N32: =COUNTIFS('스폰_편집'!$D$5:$D$3125,A32,'스폰_편집'!$B$5:$B$3125,"사용") | O32: 2 | P32: #cobblemon:is_desert; #cobblemon:is_glacial | Q32: common; uncommon | R32: region_02 | S32: cobbleventure:generation_1 | T32: =IF(M32=0,"없음",IF(N32=0,"전부 제외","사용"))
A33: 29 | B33: 니드런 | C33: nidoranf | D33: Nidoran♀ | E33: 1 | F33: generation1 | G33: poison | I33: 예 | J33: 예 | K33: 예 | L33: Cobblemon 동일 | M33: =COUNTIF('스폰_편집'!$D$5:$D$3125,A33) | N33: =COUNTIFS('스폰_편집'!$D$5:$D$3125,A33,'스폰_편집'!$B$5:$B$3125,"사용") | O33: 1 | P33: #cobblemon:is_savanna | Q33: uncommon | S33: cobbleventure:generation_1 | T33: =IF(M33=0,"없음",IF(N33=0,"전부 제외","사용"))
A34: 30 | B34: 니드리나 | C34: nidorina | D34: Nidorina | E34: 1 | F34: generation1 | G34: poison | I34: 예 | J34: 예 | K34: 예 | L34: Cobblemon 동일 | M34: =COUNTIF('스폰_편집'!$D$5:$D$3125,A34) | N34: =COUNTIFS('스폰_편집'!$D$5:$D$3125,A34,'스폰_편집'!$B$5:$B$3125,"사용") | O34: 1 | P34: #cobblemon:is_savanna | Q34: uncommon | S34: cobbleventure:generation_1 | T34: =IF(M34=0,"없음",IF(N34=0,"전부 제외","사용"))
A35: 31 | B35: 니드퀸 | C35: nidoqueen | D35: Nidoqueen | E35: 1 | F35: generation1 | G35: poison | H35: ground | I35: 예 | J35: 예 | K35: 예 | L35: Cobblemon 동일 | M35: =COUNTIF('스폰_편집'!$D$5:$D$3125,A35) | N35: =COUNTIFS('스폰_편집'!$D$5:$D$3125,A35,'스폰_편집'!$B$5:$B$3125,"사용") | O35: 1 | P35: #cobblemon:is_savanna | Q35: uncommon | S35: cobbleventure:generation_1 | T35: =IF(M35=0,"없음",IF(N35=0,"전부 제외","사용"))
A36: 32 | B36: 니드런 | C36: nidoranm | D36: Nidoran♂ | E36: 1 | F36: generation1 | G36: poison | I36: 예 | J36: 예 | K36: 예 | L36: Cobblemon 동일 | M36: =COUNTIF('스폰_편집'!$D$5:$D$3125,A36) | N36: =COUNTIFS('스폰_편집'!$D$5:$D$3125,A36,'스폰_편집'!$B$5:$B$3125,"사용") | O36: 1 | P36: #cobblemon:is_savanna | Q36: uncommon | S36: cobbleventure:generation_1 | T36: =IF(M36=0,"없음",IF(N36=0,"전부 제외","사용"))
A37: 33 | B37: 니드리노 | C37: nidorino | D37: Nidorino | E37: 1 | F37: generation1 | G37: poison | I37: 예 | J37: 예 | K37: 예 | L37: Cobblemon 동일 | M37: =COUNTIF('스폰_편집'!$D$5:$D$3125,A37) | N37: =COUNTIFS('스폰_편집'!$D$5:$D$3125,A37,'스폰_편집'!$B$5:$B$3125,"사용") | O37: 1 | P37: #cobblemon:is_savanna | Q37: uncommon | S37: cobbleventure:generation_1 | T37: =IF(M37=0,"없음",IF(N37=0,"전부 제외","사용"))
A38: 34 | B38: 니드킹 | C38: nidoking | D38: Nidoking | E38: 1 | F38: generation1 | G38: poison | H38: ground | I38: 예 | J38: 예 | K38: 예 | L38: Cobblemon 동일 | M38: =COUNTIF('스폰_편집'!$D$5:$D$3125,A38) | N38: =COUNTIFS('스폰_편집'!$D$5:$D$3125,A38,'스폰_편집'!$B$5:$B$3125,"사용") | O38: 1 | P38: #cobblemon:is_savanna | Q38: uncommon | S38: cobbleventure:generation_1 | T38: =IF(M38=0,"없음",IF(N38=0,"전부 제외","사용"))
A39: 35 | B39: 삐삐 | C39: clefairy | D39: Clefairy | E39: 1 | F39: generation1 | G39: fairy | I39: 예 | J39: 예 | K39: 예 | L39: Cobblemon 동일 | M39: =COUNTIF('스폰_편집'!$D$5:$D$3125,A39) | N39: =COUNTIFS('스폰_편집'!$D$5:$D$3125,A39,'스폰_편집'!$B$5:$B$3125,"사용") | O39: 4 | P39: #aether:is_aether; #cobblemon:is_dripstone; #cobblemon:is_hills; #cobblemon:is_magical | Q39: uncommon | S39: cobbleventure:generation_1 | T39: =IF(M39=0,"없음",IF(N39=0,"전부 제외","사용"))
A40: 36 | B40: 픽시 | C40: clefable | D40: Clefable | E40: 1 | F40: generation1 | G40: fairy | I40: 예 | J40: 예 | K40: 예 | L40: Cobblemon 동일 | M40: =COUNTIF('스폰_편집'!$D$5:$D$3125,A40) | N40: =COUNTIFS('스폰_편집'!$D$5:$D$3125,A40,'스폰_편집'!$B$5:$B$3125,"사용") | O40: 4 | P40: #aether:is_aether; #cobblemon:is_dripstone; #cobblemon:is_hills; #cobblemon:is_magical | Q40: uncommon | S40: cobbleventure:generation_1 | T40: =IF(M40=0,"없음",IF(N40=0,"전부 제외","사용"))
A41: 37 | B41: 식스테일 | C41: vulpix | D41: Vulpix | E41: 1 | F41: generation1 | G41: fire | I41: 예 | J41: 예 | K41: 예 | L41: COBBLEVERSE 수정 | M41: =COUNTIF('스폰_편집'!$D$5:$D$3125,A41) | N41: =COUNTIFS('스폰_편집'!$D$5:$D$3125,A41,'스폰_편집'!$B$5:$B$3125,"사용") | O41: 6 | P41: #cobblemon:is_forest; #cobblemon:is_snowy_forest; #cobblemon:is_snowy_taiga; #cobblemon:is_taiga; #cobblemon:nether/is_forest; minecraft:snowy_plains | Q41: common; rare; uncommon | R41: region_01 | S41: cobbleventure:generation_1 | T41: =IF(M41=0,"없음",IF(N41=0,"전부 제외","사용"))
...

Sheet 바이옴_요약
A1: 바이옴·태그별 포켓몬 출현 요약
A2: 스폰 조건의 biomes 값을 그대로 집계했습니다. #으로 시작하는 값은 바이옴 태그이며, 실제 포함 바이옴은 ‘바이옴_태그’ 시트에서 확인합니다.
A4: 바이옴·태그 | B4: 구분 | C4: 출현엔트리수 | D4: 고유포켓몬수 | E4: 제외조건수 | F4: 희귀도분포 | G4: 지역후보 | H4: 세대목록 | I4: 1세대_엔트리 | J4: 2세대_엔트리 | K4: 3세대_엔트리 | L4: 4세대_엔트리 | M4: 5세대_엔트리 | N4: 6세대_엔트리 | O4: 7세대_엔트리 | P4: 8세대_엔트리 | Q4: 9세대_엔트리 | R4: 태그원본경로
A5: #aether:is_aether | B5: 태그 | C5: 189 | D5: 108 | E5: 0 | F5: common:67; rare:23; ultra-rare:9; uncommon:90 | H5: 1; 2; 3; 4; 5; 6; 7; 8; 9 | I5: 72 | J5: 24 | K5: 13 | L5: 12 | M5: 25 | N5: 11 | O5: 5 | P5: 15 | Q5: 12
A6: #cobblemon:end | B6: 태그 | C6: 1 | D6: 1 | E6: 0 | F6: uncommon:1 | H6: 2 | I6: 0 | J6: 1 | K6: 0 | L6: 0 | M6: 0 | N6: 0 | O6: 0 | P6: 0 | Q6: 0
A7: #cobblemon:has_block/mud | B7: 태그 | C7: 15 | D7: 3 | E7: 33 | F7: common:15 | H7: 2; 5; 9 | I7: 0 | J7: 5 | K7: 0 | L7: 0 | M7: 5 | N7: 0 | O7: 0 | P7: 0 | Q7: 5
A8: #cobblemon:is_arid | B8: 태그 | C8: 103 | D8: 42 | E8: 47 | F8: common:71; rare:7; ultra-rare:7; uncommon:18 | G8: region_02 | H8: 1; 2; 3; 4; 5; 6; 8; 9 | I8: 18 | J8: 10 | K8: 13 | L8: 4 | M8: 26 | N8: 4 | O8: 0 | P8: 6 | Q8: 22 | R8: data/cobblemon/tags/worldgen/biome/is_arid.json
A9: #cobblemon:is_badlands | B9: 태그 | C9: 88 | D9: 80 | E9: 17 | F9: common:45; rare:7; ultra-rare:15; uncommon:21 | H9: 1; 2; 3; 4; 5; 6; 7; 8; 9 | I9: 5 | J9: 8 | K9: 14 | L9: 9 | M9: 19 | N9: 4 | O9: 8 | P9: 5 | Q9: 16 | R9: data/cobblemon/tags/worldgen/biome/is_badlands.json
A10: #cobblemon:is_bamboo | B10: 태그 | C10: 32 | D10: 12 | E10: 8 | F10: common:6; rare:4; ultra-rare:9; uncommon:13 | H10: 1; 3; 6; 7; 9 | I10: 4 | J10: 0 | K10: 5 | L10: 0 | M10: 0 | N10: 9 | O10: 2 | P10: 0 | Q10: 12 | R10: data/cobblemon/tags/worldgen/biome/is_bamboo.json
A11: #cobblemon:is_beach | B11: 태그 | C11: 50 | D11: 24 | E11: 23 | F11: common:20; rare:1; ultra-rare:9; uncommon:20 | H11: 1; 2; 3; 4; 5; 7; 8; 9 | I11: 14 | J11: 9 | K11: 1 | L11: 4 | M11: 9 | N11: 0 | O11: 5 | P11: 5 | Q11: 3 | R11: data/cobblemon/tags/worldgen/biome/is_beach.json
A12: #cobblemon:is_cave | B12: 태그 | C12: 10 | D12: 7 | E12: 0 | F12: common:5; rare:1; ultra-rare:2; uncommon:2 | H12: 5; 8; 9 | I12: 0 | J12: 0 | K12: 0 | L12: 0 | M12: 3 | N12: 0 | O12: 0 | P12: 6 | Q12: 1 | R12: data/cobblemon/tags/worldgen/biome/is_cave.json
A13: #cobblemon:is_cherry_blossom | B13: 태그 | C13: 9 | D13: 3 | E13: 10 | F13: common:1; uncommon:8 | H13: 6; 9 | I13: 0 | J13: 0 | K13: 0 | L13: 0 | M13: 0 | N13: 1 | O13: 0 | P13: 0 | Q13: 8 | R13: data/cobblemon/tags/worldgen/biome/is_cherry_blossom.json
A14: #cobblemon:is_coast | B14: 태그 | C14: 129 | D14: 40 | E14: 7 | F14: common:57; ultra-rare:36; uncommon:36 | H14: 1; 3; 5; 6; 7; 8; 9 | I14: 22 | J14: 0 | K14: 2 | L14: 0 | M14: 9 | N14: 25 | O14: 32 | P14: 35 | Q14: 4 | R14: data/cobblemon/tags/worldgen/biome/is_coast.json
A15: #cobblemon:is_cold | B15: 태그 | C15: 9 | D15: 5 | E15: 9 | F15: common:2; rare:1; uncommon:6 | H15: 2; 5; 7; 8 | I15: 0 | J15: 3 | K15: 0 | L15: 0 | M15: 2 | N15: 0 | O15: 1 | P15: 3 | Q15: 0 | R15: data/cobblemon/tags/worldgen/biome/is_cold.json
A16: #cobblemon:is_cold_ocean | B16: 태그 | C16: 51 | D16: 17 | E16: 25 | F16: common:34; ultra-rare:9; uncommon:8 | H16: 1; 2; 3; 4; 5; 8 | I16: 10 | J16: 10 | K16: 6 | L16: 12 | M16: 3 | N16: 0 | O16: 0 | P16: 10 | Q16: 0 | R16: data/cobblemon/tags/worldgen/biome/is_cold_ocean.json
A17: #cobblemon:is_deep_dark | B17: 태그 | C17: 23 | D17: 23 | E17: 98 | F17: common:2; rare:4; ultra-rare:1; uncommon:16 | H17: 1; 2; 3; 4; 5; 6; 7 | I17: 5 | J17: 1 | K17: 5 | L17: 1 | M17: 8 | N17: 2 | O17: 1 | P17: 0 | Q17: 0 | R17: data/cobblemon/tags/worldgen/biome/is_deep_dark.json
A18: #cobblemon:is_deep_ocean | B18: 태그 | C18: 22 | D18: 11 | E18: 5 | F18: common:9; uncommon:13 | H18: 2; 3; 4; 5 | I18: 0 | J18: 4 | K18: 12 | L18: 4 | M18: 2 | N18: 0 | O18: 0 | P18: 0 | Q18: 0 | R18: data/cobblemon/tags/worldgen/biome/is_deep_ocean.json
A19: #cobblemon:is_desert | B19: 태그 | C19: 52 | D19: 48 | E19: 14 | F19: common:28; rare:5; ultra-rare:4; uncommon:15 | G19: region_02 | H19: 1; 2; 3; 4; 5; 6; 8; 9 | I19: 5 | J19: 1 | K19: 9 | L19: 10 | M19: 17 | N19: 4 | O19: 0 | P19: 2 | Q19: 4 | R19: data/cobblemon/tags/worldgen/biome/is_desert.json
A20: #cobblemon:is_dripstone | B20: 태그 | C20: 29 | D20: 15 | E20: 23 | F20: common:5; rare:9; ultra-rare:7; uncommon:8 | H20: 1; 2; 3; 5; 6 | I20: 4 | J20: 2 | K20: 13 | L20: 0 | M20: 1 | N20: 9 | O20: 0 | P20: 0 | Q20: 0 | R20: data/cobblemon/tags/worldgen/biome/is_dripstone.json
A21: #cobblemon:is_end | B21: 태그 | C21: 54 | D21: 27 | E21: 0 | F21: common:30; rare:6; ultra-rare:7; uncommon:11 | H21: 1; 2; 3; 4; 5; 6; 7; 8 | I21: 1 | J21: 28 | K21: 3 | L21: 1 | M21: 9 | N21: 5 | O21: 6 | P21: 1 | Q21: 0 | R21: data/cobblemon/tags/worldgen/biome/is_end.json
A22: #cobblemon:is_floral | B22: 태그 | C22: 68 | D22: 57 | E22: 12 | F22: common:33; rare:9; ultra-rare:10; uncommon:16 | H22: 1; 2; 3; 4; 5; 6; 7; 8; 9 | I22: 9 | J22: 11 | K22: 7 | L22: 6 | M22: 4 | N22: 8 | O22: 7 | P22: 10 | Q22: 6 | R22: data/cobblemon/tags/worldgen/biome/is_floral.json
A23: #cobblemon:is_forest | B23: 태그 | C23: 188 | D23: 130 | E23: 8 | F23: common:94; rare:18; ultra-rare:30; uncommon:46 | G23: region_01 | H23: 1; 2; 3; 4; 5; 6; 7; 8; 9 | I23: 22 | J23: 11 | K23: 27 | L23: 30 | M23: 30 | N23: 13 | O23: 12 | P23: 19 | Q23: 24 | R23: data/cobblemon/tags/worldgen/biome/is_forest.json
A24: #cobblemon:is_freezing | B24: 태그 | C24: 43 | D24: 26 | E24: 316 | F24: common:22; rare:2; ultra-rare:1; uncommon:18 | H24: 1; 2; 3; 4; 5; 6; 8; 9 | I24: 12 | J24: 2 | K24: 1 | L24: 7 | M24: 9 | N24: 5 | O24: 0 | P24: 6 | Q24: 1 | R24: data/cobblemon/tags/worldgen/biome/is_freezing.json
A25: #cobblemon:is_freshwater | B25: 태그 | C25: 166 | D25: 47 | E25: 0 | F25: common:113; rare:2; ultra-rare:30; uncommon:21 | G25: region_02 | H25: 1; 2; 3; 4; 5; 6; 7; 8; 9 | I25: 51 | J25: 6 | K25: 20 | L25: 17 | M25: 32 | N25: 10 | O25: 13 | P25: 12 | Q25: 5 | R25: data/cobblemon/tags/worldgen/biome/is_freshwater.json
A26: #cobblemon:is_frozen_ocean | B26: 태그 | C26: 81 | D26: 23 | E26: 42 | F26: common:61; ultra-rare:15; uncommon:5 | H26: 1; 2; 3; 4; 5; 6; 8; 9 | I26: 21 | J26: 4 | K26: 15 | L26: 21 | M26: 2 | N26: 9 | O26: 0 | P26: 7 | Q26: 2 | R26: data/cobblemon/tags/worldgen/biome/is_frozen_ocean.json
